
<?xml version="1.0" ?>

<robot name="Manipulator">

  <!-- Colors -->
  <material name="Black">
    <color rgba="0 0 0 1.0"/>
  </material>
  <material name="Grey">
    <color rgba="0.2 0.2 0.2 1.0"/>
  </material>
  <material name="Orange">
    <color rgba="1.0 0.423529411765 0.0392156862745 1.0"/>
  </material>
  <material name="Blue">
  <color rgba="0.0 0.0 1 1.0"/>      
  </material>
  <material name="Red">
    <color rgba="1 0 0 1.0"/>      
  </material>

  <!-- Base Link -->
  <link name="SprutBase">
    <inertial>
      <origin rpy="0 0 0" xyz="0 0 0"/>
      <mass value="100"/>
      <inertia ixx="9.3" ixy="0" ixz="0" iyy="9.3" iyz="0" izz="9.3"/>
    </inertial>
    <!-- visual>
      <origin rpy="0 0 0" xyz="0 0 0"/>
      <geometry>
        <box size="1 1 0" />
      </geometry>
      <material name="Black"/>
    </visual -->
  </link>

  <!-- Section 0 -->

  <joint name="Joint_0a" type="revolute">
    <parent link="SprutBase"/>
    <child link="Block0"/>
    <origin rpy="0 0 0" xyz="0 0 0.028000"/>
    <axis xyz="0 1 0"/>
    <limit effort="1000.0" lower="-1.0" upper="1.0" velocity="1000.0"/>
  </joint>

  <link name="Block0">
    <inertial>
      <origin rpy="0 0 0" xyz="0 0 0"/>
      <mass value="1"/>
      <inertia ixx="0.01" ixy="0" ixz="0" iyy="0.01" iyz="0" izz="0.01"/>
    </inertial>
    <visual>
      <origin rpy="0 0 0" xyz="0 0 0"/>
      <geometry>
        <box size="0.023 0.023 0.005"/>
      </geometry>
      <material name="Grey"/>
    </visual>
  </link>

  <joint name="Joint_0b" type="revolute">
    <parent link="Block0"/>
    <child link="PlateFixLink0"/>
    <origin rpy="0 0 0" xyz="0 0 0"/>
    <axis xyz="-1 0 0"/>
    <limit effort="1000.0" lower="-1.0" upper="1.0" velocity="1000.0"/>
  </joint>

  <link name="PlateFixLink0">
    <inertial>
      <origin rpy="0 0 0" xyz="0 0 0"/>
      <mass value="1"/>
      <inertia ixx="0.01" ixy="0" ixz="0" iyy="0.01" iyz="0" izz="0.01"/>
    </inertial>
  </link>

  <joint name="PlateFixJoint0b" type="fixed">
    <parent link="PlateFixLink0"/>
    <child link="Plate0"/>
    <origin rpy="0 0 0" xyz="0 0 0.028000"/>
    <axis xyz="-1 0 0"/>
  </joint>

  <link name="Plate0">
    <inertial>
      <origin rpy="0 0 0" xyz="0 0 0"/>
      <mass value="1"/>
      <inertia ixx="0.01" ixy="0" ixz="0" iyy="0.01" iyz="0" izz="0.01"/>
    </inertial>
    <visual>
      <origin rpy="0 0 0" xyz="0 0 0"/>
      <geometry>
        <cylinder radius="0.035000" length="0.025"/>
      </geometry>
      <material name="Grey"/>
    </visual>
  </link>

  <!-- Section 1 -->

  <joint name="Joint_1a" type="revolute">
    <parent link="Plate0"/>
    <child link="Block1"/>
    <origin rpy="0 0 0" xyz="0 0 0.028000"/>
    <axis xyz="0 1 0"/>
    <limit effort="1000.0" lower="-1.0" upper="1.0" velocity="1000.0"/>
  </joint>

  <link name="Block1">
    <inertial>
      <origin rpy="0 0 0" xyz="0 0 0"/>
      <mass value="1"/>
      <inertia ixx="0.01" ixy="0" ixz="0" iyy="0.01" iyz="0" izz="0.01"/>
    </inertial>
    <visual>
      <origin rpy="0 0 0" xyz="0 0 0"/>
      <geometry>
        <box size="0.023 0.023 0.005"/>
      </geometry>
      <material name="Grey"/>
    </visual>
  </link>

  <joint name="Joint_1b" type="revolute">
    <parent link="Block1"/>
    <child link="PlateFixLink1"/>
    <origin rpy="0 0 0" xyz="0 0 0"/>
    <axis xyz="-1 0 0"/>
    <limit effort="1000.0" lower="-1.0" upper="1.0" velocity="1000.0"/>
  </joint>

  <link name="PlateFixLink1">
    <inertial>
      <origin rpy="0 0 0" xyz="0 0 0"/>
      <mass value="1"/>
      <inertia ixx="0.01" ixy="0" ixz="0" iyy="0.01" iyz="0" izz="0.01"/>
    </inertial>
  </link>

  <joint name="PlateFixJoint1b" type="fixed">
    <parent link="PlateFixLink1"/>
    <child link="Plate1"/>
    <origin rpy="0 0 0" xyz="0 0 0.028000"/>
    <axis xyz="-1 0 0"/>
  </joint>

  <link name="Plate1">
    <inertial>
      <origin rpy="0 0 0" xyz="0 0 0"/>
      <mass value="1"/>
      <inertia ixx="0.01" ixy="0" ixz="0" iyy="0.01" iyz="0" izz="0.01"/>
    </inertial>
    <visual>
      <origin rpy="0 0 0" xyz="0 0 0"/>
      <geometry>
        <cylinder radius="0.035000" length="0.025"/>
      </geometry>
      <material name="Grey"/>
    </visual>
  </link>

  <!-- Section 2 -->

  <joint name="Joint_2a" type="revolute">
    <parent link="Plate1"/>
    <child link="Block2"/>
    <origin rpy="0 0 0" xyz="0 0 0.028000"/>
    <axis xyz="0 1 0"/>
    <limit effort="1000.0" lower="-1.0" upper="1.0" velocity="1000.0"/>
  </joint>

  <link name="Block2">
    <inertial>
      <origin rpy="0 0 0" xyz="0 0 0"/>
      <mass value="1"/>
      <inertia ixx="0.01" ixy="0" ixz="0" iyy="0.01" iyz="0" izz="0.01"/>
    </inertial>
    <visual>
      <origin rpy="0 0 0" xyz="0 0 0"/>
      <geometry>
        <box size="0.023 0.023 0.005"/>
      </geometry>
      <material name="Grey"/>
    </visual>
  </link>

  <joint name="Joint_2b" type="revolute">
    <parent link="Block2"/>
    <child link="PlateFixLink2"/>
    <origin rpy="0 0 0" xyz="0 0 0"/>
    <axis xyz="-1 0 0"/>
    <limit effort="1000.0" lower="-1.0" upper="1.0" velocity="1000.0"/>
  </joint>

  <link name="PlateFixLink2">
    <inertial>
      <origin rpy="0 0 0" xyz="0 0 0"/>
      <mass value="1"/>
      <inertia ixx="0.01" ixy="0" ixz="0" iyy="0.01" iyz="0" izz="0.01"/>
    </inertial>
  </link>

  <joint name="PlateFixJoint2b" type="fixed">
    <parent link="PlateFixLink2"/>
    <child link="Plate2"/>
    <origin rpy="0 0 0" xyz="0 0 0.028000"/>
    <axis xyz="-1 0 0"/>
  </joint>

  <link name="Plate2">
    <inertial>
      <origin rpy="0 0 0" xyz="0 0 0"/>
      <mass value="1"/>
      <inertia ixx="0.01" ixy="0" ixz="0" iyy="0.01" iyz="0" izz="0.01"/>
    </inertial>
    <visual>
      <origin rpy="0 0 0" xyz="0 0 0"/>
      <geometry>
        <cylinder radius="0.035000" length="0.025"/>
      </geometry>
      <material name="Grey"/>
    </visual>
  </link>

  <!-- Section 3 -->

  <joint name="Joint_3a" type="revolute">
    <parent link="Plate2"/>
    <child link="Block3"/>
    <origin rpy="0 0 0" xyz="0 0 0.028000"/>
    <axis xyz="0 1 0"/>
    <limit effort="1000.0" lower="-1.0" upper="1.0" velocity="1000.0"/>
  </joint>

  <link name="Block3">
    <inertial>
      <origin rpy="0 0 0" xyz="0 0 0"/>
      <mass value="1"/>
      <inertia ixx="0.01" ixy="0" ixz="0" iyy="0.01" iyz="0" izz="0.01"/>
    </inertial>
    <visual>
      <origin rpy="0 0 0" xyz="0 0 0"/>
      <geometry>
        <box size="0.023 0.023 0.005"/>
      </geometry>
      <material name="Grey"/>
    </visual>
  </link>

  <joint name="Joint_3b" type="revolute">
    <parent link="Block3"/>
    <child link="PlateFixLink3"/>
    <origin rpy="0 0 0" xyz="0 0 0"/>
    <axis xyz="-1 0 0"/>
    <limit effort="1000.0" lower="-1.0" upper="1.0" velocity="1000.0"/>
  </joint>

  <link name="PlateFixLink3">
    <inertial>
      <origin rpy="0 0 0" xyz="0 0 0"/>
      <mass value="1"/>
      <inertia ixx="0.01" ixy="0" ixz="0" iyy="0.01" iyz="0" izz="0.01"/>
    </inertial>
  </link>

  <joint name="PlateFixJoint3b" type="fixed">
    <parent link="PlateFixLink3"/>
    <child link="Plate3"/>
    <origin rpy="0 0 0" xyz="0 0 0.028000"/>
    <axis xyz="-1 0 0"/>
  </joint>

  <link name="Plate3">
    <inertial>
      <origin rpy="0 0 0" xyz="0 0 0"/>
      <mass value="1"/>
      <inertia ixx="0.01" ixy="0" ixz="0" iyy="0.01" iyz="0" izz="0.01"/>
    </inertial>
    <visual>
      <origin rpy="0 0 0" xyz="0 0 0"/>
      <geometry>
        <cylinder radius="0.035000" length="0.025"/>
      </geometry>
      <material name="Black"/>
    </visual>
  </link>

  <!-- Section 4 -->

  <joint name="Joint_4a" type="revolute">
    <parent link="Plate3"/>
    <child link="Block4"/>
    <origin rpy="0 0 0" xyz="0 0 0.028000"/>
    <axis xyz="0 1 0"/>
    <limit effort="1000.0" lower="-1.0" upper="1.0" velocity="1000.0"/>
  </joint>

  <link name="Block4">
    <inertial>
      <origin rpy="0 0 0" xyz="0 0 0"/>
      <mass value="1"/>
      <inertia ixx="0.01" ixy="0" ixz="0" iyy="0.01" iyz="0" izz="0.01"/>
    </inertial>
    <visual>
      <origin rpy="0 0 0" xyz="0 0 0"/>
      <geometry>
        <box size="0.023 0.023 0.005"/>
      </geometry>
      <material name="Grey"/>
    </visual>
  </link>

  <joint name="Joint_4b" type="revolute">
    <parent link="Block4"/>
    <child link="PlateFixLink4"/>
    <origin rpy="0 0 0" xyz="0 0 0"/>
    <axis xyz="-1 0 0"/>
    <limit effort="1000.0" lower="-1.0" upper="1.0" velocity="1000.0"/>
  </joint>

  <link name="PlateFixLink4">
    <inertial>
      <origin rpy="0 0 0" xyz="0 0 0"/>
      <mass value="1"/>
      <inertia ixx="0.01" ixy="0" ixz="0" iyy="0.01" iyz="0" izz="0.01"/>
    </inertial>
  </link>

  <joint name="PlateFixJoint4b" type="fixed">
    <parent link="PlateFixLink4"/>
    <child link="Plate4"/>
    <origin rpy="0 0 0" xyz="0 0 0.028000"/>
    <axis xyz="-1 0 0"/>
  </joint>

  <link name="Plate4">
    <inertial>
      <origin rpy="0 0 0" xyz="0 0 0"/>
      <mass value="1"/>
      <inertia ixx="0.01" ixy="0" ixz="0" iyy="0.01" iyz="0" izz="0.01"/>
    </inertial>
    <visual>
      <origin rpy="0 0 0" xyz="0 0 0"/>
      <geometry>
        <cylinder radius="0.035000" length="0.025"/>
      </geometry>
      <material name="Grey"/>
    </visual>
  </link>

  <!-- Section 5 -->

  <joint name="Joint_5a" type="revolute">
    <parent link="Plate4"/>
    <child link="Block5"/>
    <origin rpy="0 0 0" xyz="0 0 0.028000"/>
    <axis xyz="0 1 0"/>
    <limit effort="1000.0" lower="-1.0" upper="1.0" velocity="1000.0"/>
  </joint>

  <link name="Block5">
    <inertial>
      <origin rpy="0 0 0" xyz="0 0 0"/>
      <mass value="1"/>
      <inertia ixx="0.01" ixy="0" ixz="0" iyy="0.01" iyz="0" izz="0.01"/>
    </inertial>
    <visual>
      <origin rpy="0 0 0" xyz="0 0 0"/>
      <geometry>
        <box size="0.023 0.023 0.005"/>
      </geometry>
      <material name="Grey"/>
    </visual>
  </link>

  <joint name="Joint_5b" type="revolute">
    <parent link="Block5"/>
    <child link="PlateFixLink5"/>
    <origin rpy="0 0 0" xyz="0 0 0"/>
    <axis xyz="-1 0 0"/>
    <limit effort="1000.0" lower="-1.0" upper="1.0" velocity="1000.0"/>
  </joint>

  <link name="PlateFixLink5">
    <inertial>
      <origin rpy="0 0 0" xyz="0 0 0"/>
      <mass value="1"/>
      <inertia ixx="0.01" ixy="0" ixz="0" iyy="0.01" iyz="0" izz="0.01"/>
    </inertial>
  </link>

  <joint name="PlateFixJoint5b" type="fixed">
    <parent link="PlateFixLink5"/>
    <child link="Plate5"/>
    <origin rpy="0 0 0" xyz="0 0 0.028000"/>
    <axis xyz="-1 0 0"/>
  </joint>

  <link name="Plate5">
    <inertial>
      <origin rpy="0 0 0" xyz="0 0 0"/>
      <mass value="1"/>
      <inertia ixx="0.01" ixy="0" ixz="0" iyy="0.01" iyz="0" izz="0.01"/>
    </inertial>
    <visual>
      <origin rpy="0 0 0" xyz="0 0 0"/>
      <geometry>
        <cylinder radius="0.035000" length="0.025"/>
      </geometry>
      <material name="Grey"/>
    </visual>
  </link>

  <!-- Section 6 -->

  <joint name="Joint_6a" type="revolute">
    <parent link="Plate5"/>
    <child link="Block6"/>
    <origin rpy="0 0 0" xyz="0 0 0.028000"/>
    <axis xyz="0 1 0"/>
    <limit effort="1000.0" lower="-1.0" upper="1.0" velocity="1000.0"/>
  </joint>

  <link name="Block6">
    <inertial>
      <origin rpy="0 0 0" xyz="0 0 0"/>
      <mass value="1"/>
      <inertia ixx="0.01" ixy="0" ixz="0" iyy="0.01" iyz="0" izz="0.01"/>
    </inertial>
    <visual>
      <origin rpy="0 0 0" xyz="0 0 0"/>
      <geometry>
        <box size="0.023 0.023 0.005"/>
      </geometry>
      <material name="Grey"/>
    </visual>
  </link>

  <joint name="Joint_6b" type="revolute">
    <parent link="Block6"/>
    <child link="PlateFixLink6"/>
    <origin rpy="0 0 0" xyz="0 0 0"/>
    <axis xyz="-1 0 0"/>
    <limit effort="1000.0" lower="-1.0" upper="1.0" velocity="1000.0"/>
  </joint>

  <link name="PlateFixLink6">
    <inertial>
      <origin rpy="0 0 0" xyz="0 0 0"/>
      <mass value="1"/>
      <inertia ixx="0.01" ixy="0" ixz="0" iyy="0.01" iyz="0" izz="0.01"/>
    </inertial>
  </link>

  <joint name="PlateFixJoint6b" type="fixed">
    <parent link="PlateFixLink6"/>
    <child link="Plate6"/>
    <origin rpy="0 0 0" xyz="0 0 0.028000"/>
    <axis xyz="-1 0 0"/>
  </joint>

  <link name="Plate6">
    <inertial>
      <origin rpy="0 0 0" xyz="0 0 0"/>
      <mass value="1"/>
      <inertia ixx="0.01" ixy="0" ixz="0" iyy="0.01" iyz="0" izz="0.01"/>
    </inertial>
    <visual>
      <origin rpy="0 0 0" xyz="0 0 0"/>
      <geometry>
        <cylinder radius="0.035000" length="0.025"/>
      </geometry>
      <material name="Grey"/>
    </visual>
  </link>

  <!-- Section 7 -->

  <joint name="Joint_7a" type="revolute">
    <parent link="Plate6"/>
    <child link="Block7"/>
    <origin rpy="0 0 0" xyz="0 0 0.028000"/>
    <axis xyz="0 1 0"/>
    <limit effort="1000.0" lower="-1.0" upper="1.0" velocity="1000.0"/>
  </joint>

  <link name="Block7">
    <inertial>
      <origin rpy="0 0 0" xyz="0 0 0"/>
      <mass value="1"/>
      <inertia ixx="0.01" ixy="0" ixz="0" iyy="0.01" iyz="0" izz="0.01"/>
    </inertial>
    <visual>
      <origin rpy="0 0 0" xyz="0 0 0"/>
      <geometry>
        <box size="0.023 0.023 0.005"/>
      </geometry>
      <material name="Grey"/>
    </visual>
  </link>

  <joint name="Joint_7b" type="revolute">
    <parent link="Block7"/>
    <child link="PlateFixLink7"/>
    <origin rpy="0 0 0" xyz="0 0 0"/>
    <axis xyz="-1 0 0"/>
    <limit effort="1000.0" lower="-1.0" upper="1.0" velocity="1000.0"/>
  </joint>

  <link name="PlateFixLink7">
    <inertial>
      <origin rpy="0 0 0" xyz="0 0 0"/>
      <mass value="1"/>
      <inertia ixx="0.01" ixy="0" ixz="0" iyy="0.01" iyz="0" izz="0.01"/>
    </inertial>
  </link>

  <joint name="PlateFixJoint7b" type="fixed">
    <parent link="PlateFixLink7"/>
    <child link="Plate7"/>
    <origin rpy="0 0 0" xyz="0 0 0.028000"/>
    <axis xyz="-1 0 0"/>
  </joint>

  <link name="Plate7">
    <inertial>
      <origin rpy="0 0 0" xyz="0 0 0"/>
      <mass value="1"/>
      <inertia ixx="0.01" ixy="0" ixz="0" iyy="0.01" iyz="0" izz="0.01"/>
    </inertial>
    <visual>
      <origin rpy="0 0 0" xyz="0 0 0"/>
      <geometry>
        <cylinder radius="0.035000" length="0.025"/>
      </geometry>
      <material name="Black"/>
    </visual>
  </link>

  <!-- Section 8 -->

  <joint name="Joint_8a" type="revolute">
    <parent link="Plate7"/>
    <child link="Block8"/>
    <origin rpy="0 0 0" xyz="0 0 0.028000"/>
    <axis xyz="0 1 0"/>
    <limit effort="1000.0" lower="-1.0" upper="1.0" velocity="1000.0"/>
  </joint>

  <link name="Block8">
    <inertial>
      <origin rpy="0 0 0" xyz="0 0 0"/>
      <mass value="1"/>
      <inertia ixx="0.01" ixy="0" ixz="0" iyy="0.01" iyz="0" izz="0.01"/>
    </inertial>
    <visual>
      <origin rpy="0 0 0" xyz="0 0 0"/>
      <geometry>
        <box size="0.023 0.023 0.005"/>
      </geometry>
      <material name="Grey"/>
    </visual>
  </link>

  <joint name="Joint_8b" type="revolute">
    <parent link="Block8"/>
    <child link="PlateFixLink8"/>
    <origin rpy="0 0 0" xyz="0 0 0"/>
    <axis xyz="-1 0 0"/>
    <limit effort="1000.0" lower="-1.0" upper="1.0" velocity="1000.0"/>
  </joint>

  <link name="PlateFixLink8">
    <inertial>
      <origin rpy="0 0 0" xyz="0 0 0"/>
      <mass value="1"/>
      <inertia ixx="0.01" ixy="0" ixz="0" iyy="0.01" iyz="0" izz="0.01"/>
    </inertial>
  </link>

  <joint name="PlateFixJoint8b" type="fixed">
    <parent link="PlateFixLink8"/>
    <child link="Plate8"/>
    <origin rpy="0 0 0" xyz="0 0 0.028000"/>
    <axis xyz="-1 0 0"/>
  </joint>

  <link name="Plate8">
    <inertial>
      <origin rpy="0 0 0" xyz="0 0 0"/>
      <mass value="1"/>
      <inertia ixx="0.01" ixy="0" ixz="0" iyy="0.01" iyz="0" izz="0.01"/>
    </inertial>
    <visual>
      <origin rpy="0 0 0" xyz="0 0 0"/>
      <geometry>
        <cylinder radius="0.035000" length="0.025"/>
      </geometry>
      <material name="Grey"/>
    </visual>
  </link>

  <!-- Section 9 -->

  <joint name="Joint_9a" type="revolute">
    <parent link="Plate8"/>
    <child link="Block9"/>
    <origin rpy="0 0 0" xyz="0 0 0.028000"/>
    <axis xyz="0 1 0"/>
    <limit effort="1000.0" lower="-1.0" upper="1.0" velocity="1000.0"/>
  </joint>

  <link name="Block9">
    <inertial>
      <origin rpy="0 0 0" xyz="0 0 0"/>
      <mass value="1"/>
      <inertia ixx="0.01" ixy="0" ixz="0" iyy="0.01" iyz="0" izz="0.01"/>
    </inertial>
    <visual>
      <origin rpy="0 0 0" xyz="0 0 0"/>
      <geometry>
        <box size="0.023 0.023 0.005"/>
      </geometry>
      <material name="Grey"/>
    </visual>
  </link>

  <joint name="Joint_9b" type="revolute">
    <parent link="Block9"/>
    <child link="PlateFixLink9"/>
    <origin rpy="0 0 0" xyz="0 0 0"/>
    <axis xyz="-1 0 0"/>
    <limit effort="1000.0" lower="-1.0" upper="1.0" velocity="1000.0"/>
  </joint>

  <link name="PlateFixLink9">
    <inertial>
      <origin rpy="0 0 0" xyz="0 0 0"/>
      <mass value="1"/>
      <inertia ixx="0.01" ixy="0" ixz="0" iyy="0.01" iyz="0" izz="0.01"/>
    </inertial>
  </link>

  <joint name="PlateFixJoint9b" type="fixed">
    <parent link="PlateFixLink9"/>
    <child link="Plate9"/>
    <origin rpy="0 0 0" xyz="0 0 0.028000"/>
    <axis xyz="-1 0 0"/>
  </joint>

  <link name="Plate9">
    <inertial>
      <origin rpy="0 0 0" xyz="0 0 0"/>
      <mass value="1"/>
      <inertia ixx="0.01" ixy="0" ixz="0" iyy="0.01" iyz="0" izz="0.01"/>
    </inertial>
    <visual>
      <origin rpy="0 0 0" xyz="0 0 0"/>
      <geometry>
        <cylinder radius="0.035000" length="0.025"/>
      </geometry>
      <material name="Grey"/>
    </visual>
  </link>

  <!-- Section 10 -->

  <joint name="Joint_10a" type="revolute">
    <parent link="Plate9"/>
    <child link="Block10"/>
    <origin rpy="0 0 0" xyz="0 0 0.028000"/>
    <axis xyz="0 1 0"/>
    <limit effort="1000.0" lower="-1.0" upper="1.0" velocity="1000.0"/>
  </joint>

  <link name="Block10">
    <inertial>
      <origin rpy="0 0 0" xyz="0 0 0"/>
      <mass value="1"/>
      <inertia ixx="0.01" ixy="0" ixz="0" iyy="0.01" iyz="0" izz="0.01"/>
    </inertial>
    <visual>
      <origin rpy="0 0 0" xyz="0 0 0"/>
      <geometry>
        <box size="0.023 0.023 0.005"/>
      </geometry>
      <material name="Grey"/>
    </visual>
  </link>

  <joint name="Joint_10b" type="revolute">
    <parent link="Block10"/>
    <child link="PlateFixLink10"/>
    <origin rpy="0 0 0" xyz="0 0 0"/>
    <axis xyz="-1 0 0"/>
    <limit effort="1000.0" lower="-1.0" upper="1.0" velocity="1000.0"/>
  </joint>

  <link name="PlateFixLink10">
    <inertial>
      <origin rpy="0 0 0" xyz="0 0 0"/>
      <mass value="1"/>
      <inertia ixx="0.01" ixy="0" ixz="0" iyy="0.01" iyz="0" izz="0.01"/>
    </inertial>
  </link>

  <joint name="PlateFixJoint10b" type="fixed">
    <parent link="PlateFixLink10"/>
    <child link="Plate10"/>
    <origin rpy="0 0 0" xyz="0 0 0.028000"/>
    <axis xyz="-1 0 0"/>
  </joint>

  <link name="Plate10">
    <inertial>
      <origin rpy="0 0 0" xyz="0 0 0"/>
      <mass value="1"/>
      <inertia ixx="0.01" ixy="0" ixz="0" iyy="0.01" iyz="0" izz="0.01"/>
    </inertial>
    <visual>
      <origin rpy="0 0 0" xyz="0 0 0"/>
      <geometry>
        <cylinder radius="0.035000" length="0.025"/>
      </geometry>
      <material name="Grey"/>
    </visual>
  </link>

  <!-- Section 11 -->

  <joint name="Joint_11a" type="revolute">
    <parent link="Plate10"/>
    <child link="Block11"/>
    <origin rpy="0 0 0" xyz="0 0 0.028000"/>
    <axis xyz="0 1 0"/>
    <limit effort="1000.0" lower="-1.0" upper="1.0" velocity="1000.0"/>
  </joint>

  <link name="Block11">
    <inertial>
      <origin rpy="0 0 0" xyz="0 0 0"/>
      <mass value="1"/>
      <inertia ixx="0.01" ixy="0" ixz="0" iyy="0.01" iyz="0" izz="0.01"/>
    </inertial>
    <visual>
      <origin rpy="0 0 0" xyz="0 0 0"/>
      <geometry>
        <box size="0.023 0.023 0.005"/>
      </geometry>
      <material name="Grey"/>
    </visual>
  </link>

  <joint name="Joint_11b" type="revolute">
    <parent link="Block11"/>
    <child link="PlateFixLink11"/>
    <origin rpy="0 0 0" xyz="0 0 0"/>
    <axis xyz="-1 0 0"/>
    <limit effort="1000.0" lower="-1.0" upper="1.0" velocity="1000.0"/>
  </joint>

  <link name="PlateFixLink11">
    <inertial>
      <origin rpy="0 0 0" xyz="0 0 0"/>
      <mass value="1"/>
      <inertia ixx="0.01" ixy="0" ixz="0" iyy="0.01" iyz="0" izz="0.01"/>
    </inertial>
  </link>

  <joint name="PlateFixJoint11b" type="fixed">
    <parent link="PlateFixLink11"/>
    <child link="Plate11"/>
    <origin rpy="0 0 0" xyz="0 0 0.028000"/>
    <axis xyz="-1 0 0"/>
  </joint>

  <link name="Plate11">
    <inertial>
      <origin rpy="0 0 0" xyz="0 0 0"/>
      <mass value="1"/>
      <inertia ixx="0.01" ixy="0" ixz="0" iyy="0.01" iyz="0" izz="0.01"/>
    </inertial>
    <visual>
      <origin rpy="0 0 0" xyz="0 0 0"/>
      <geometry>
        <cylinder radius="0.035000" length="0.025"/>
      </geometry>
      <material name="Black"/>
    </visual>
  </link>

  <!-- Section 12 -->

  <joint name="Joint_12a" type="revolute">
    <parent link="Plate11"/>
    <child link="Block12"/>
    <origin rpy="0 0 0" xyz="0 0 0.028000"/>
    <axis xyz="0 1 0"/>
    <limit effort="1000.0" lower="-1.0" upper="1.0" velocity="1000.0"/>
  </joint>

  <link name="Block12">
    <inertial>
      <origin rpy="0 0 0" xyz="0 0 0"/>
      <mass value="1"/>
      <inertia ixx="0.01" ixy="0" ixz="0" iyy="0.01" iyz="0" izz="0.01"/>
    </inertial>
    <visual>
      <origin rpy="0 0 0" xyz="0 0 0"/>
      <geometry>
        <box size="0.023 0.023 0.005"/>
      </geometry>
      <material name="Grey"/>
    </visual>
  </link>

  <joint name="Joint_12b" type="revolute">
    <parent link="Block12"/>
    <child link="PlateFixLink12"/>
    <origin rpy="0 0 0" xyz="0 0 0"/>
    <axis xyz="-1 0 0"/>
    <limit effort="1000.0" lower="-1.0" upper="1.0" velocity="1000.0"/>
  </joint>

  <link name="PlateFixLink12">
    <inertial>
      <origin rpy="0 0 0" xyz="0 0 0"/>
      <mass value="1"/>
      <inertia ixx="0.01" ixy="0" ixz="0" iyy="0.01" iyz="0" izz="0.01"/>
    </inertial>
  </link>

  <joint name="PlateFixJoint12b" type="fixed">
    <parent link="PlateFixLink12"/>
    <child link="Plate12"/>
    <origin rpy="0 0 0" xyz="0 0 0.028000"/>
    <axis xyz="-1 0 0"/>
  </joint>

  <link name="Plate12">
    <inertial>
      <origin rpy="0 0 0" xyz="0 0 0"/>
      <mass value="1"/>
      <inertia ixx="0.01" ixy="0" ixz="0" iyy="0.01" iyz="0" izz="0.01"/>
    </inertial>
    <visual>
      <origin rpy="0 0 0" xyz="0 0 0"/>
      <geometry>
        <cylinder radius="0.035000" length="0.025"/>
      </geometry>
      <material name="Grey"/>
    </visual>
  </link>

  <!-- Section 13 -->

  <joint name="Joint_13a" type="revolute">
    <parent link="Plate12"/>
    <child link="Block13"/>
    <origin rpy="0 0 0" xyz="0 0 0.028000"/>
    <axis xyz="0 1 0"/>
    <limit effort="1000.0" lower="-1.0" upper="1.0" velocity="1000.0"/>
  </joint>

  <link name="Block13">
    <inertial>
      <origin rpy="0 0 0" xyz="0 0 0"/>
      <mass value="1"/>
      <inertia ixx="0.01" ixy="0" ixz="0" iyy="0.01" iyz="0" izz="0.01"/>
    </inertial>
    <visual>
      <origin rpy="0 0 0" xyz="0 0 0"/>
      <geometry>
        <box size="0.023 0.023 0.005"/>
      </geometry>
      <material name="Grey"/>
    </visual>
  </link>

  <joint name="Joint_13b" type="revolute">
    <parent link="Block13"/>
    <child link="PlateFixLink13"/>
    <origin rpy="0 0 0" xyz="0 0 0"/>
    <axis xyz="-1 0 0"/>
    <limit effort="1000.0" lower="-1.0" upper="1.0" velocity="1000.0"/>
  </joint>

  <link name="PlateFixLink13">
    <inertial>
      <origin rpy="0 0 0" xyz="0 0 0"/>
      <mass value="1"/>
      <inertia ixx="0.01" ixy="0" ixz="0" iyy="0.01" iyz="0" izz="0.01"/>
    </inertial>
  </link>

  <joint name="PlateFixJoint13b" type="fixed">
    <parent link="PlateFixLink13"/>
    <child link="Plate13"/>
    <origin rpy="0 0 0" xyz="0 0 0.028000"/>
    <axis xyz="-1 0 0"/>
  </joint>

  <link name="Plate13">
    <inertial>
      <origin rpy="0 0 0" xyz="0 0 0"/>
      <mass value="1"/>
      <inertia ixx="0.01" ixy="0" ixz="0" iyy="0.01" iyz="0" izz="0.01"/>
    </inertial>
    <visual>
      <origin rpy="0 0 0" xyz="0 0 0"/>
      <geometry>
        <cylinder radius="0.035000" length="0.025"/>
      </geometry>
      <material name="Grey"/>
    </visual>
  </link>

  <!-- Section 14 -->

  <joint name="Joint_14a" type="revolute">
    <parent link="Plate13"/>
    <child link="Block14"/>
    <origin rpy="0 0 0" xyz="0 0 0.028000"/>
    <axis xyz="0 1 0"/>
    <limit effort="1000.0" lower="-1.0" upper="1.0" velocity="1000.0"/>
  </joint>

  <link name="Block14">
    <inertial>
      <origin rpy="0 0 0" xyz="0 0 0"/>
      <mass value="1"/>
      <inertia ixx="0.01" ixy="0" ixz="0" iyy="0.01" iyz="0" izz="0.01"/>
    </inertial>
    <visual>
      <origin rpy="0 0 0" xyz="0 0 0"/>
      <geometry>
        <box size="0.023 0.023 0.005"/>
      </geometry>
      <material name="Grey"/>
    </visual>
  </link>

  <joint name="Joint_14b" type="revolute">
    <parent link="Block14"/>
    <child link="PlateFixLink14"/>
    <origin rpy="0 0 0" xyz="0 0 0"/>
    <axis xyz="-1 0 0"/>
    <limit effort="1000.0" lower="-1.0" upper="1.0" velocity="1000.0"/>
  </joint>

  <link name="PlateFixLink14">
    <inertial>
      <origin rpy="0 0 0" xyz="0 0 0"/>
      <mass value="1"/>
      <inertia ixx="0.01" ixy="0" ixz="0" iyy="0.01" iyz="0" izz="0.01"/>
    </inertial>
  </link>

  <joint name="PlateFixJoint14b" type="fixed">
    <parent link="PlateFixLink14"/>
    <child link="Plate14"/>
    <origin rpy="0 0 0" xyz="0 0 0.028000"/>
    <axis xyz="-1 0 0"/>
  </joint>

  <link name="Plate14">
    <inertial>
      <origin rpy="0 0 0" xyz="0 0 0"/>
      <mass value="1"/>
      <inertia ixx="0.01" ixy="0" ixz="0" iyy="0.01" iyz="0" izz="0.01"/>
    </inertial>
    <visual>
      <origin rpy="0 0 0" xyz="0 0 0"/>
      <geometry>
        <cylinder radius="0.035000" length="0.025"/>
      </geometry>
      <material name="Grey"/>
    </visual>
  </link>

  <!-- Section 15 -->

  <joint name="Joint_15a" type="revolute">
    <parent link="Plate14"/>
    <child link="Block15"/>
    <origin rpy="0 0 0" xyz="0 0 0.028000"/>
    <axis xyz="0 1 0"/>
    <limit effort="1000.0" lower="-1.0" upper="1.0" velocity="1000.0"/>
  </joint>

  <link name="Block15">
    <inertial>
      <origin rpy="0 0 0" xyz="0 0 0"/>
      <mass value="1"/>
      <inertia ixx="0.01" ixy="0" ixz="0" iyy="0.01" iyz="0" izz="0.01"/>
    </inertial>
    <visual>
      <origin rpy="0 0 0" xyz="0 0 0"/>
      <geometry>
        <box size="0.023 0.023 0.005"/>
      </geometry>
      <material name="Grey"/>
    </visual>
  </link>

  <joint name="Joint_15b" type="revolute">
    <parent link="Block15"/>
    <child link="PlateFixLink15"/>
    <origin rpy="0 0 0" xyz="0 0 0"/>
    <axis xyz="-1 0 0"/>
    <limit effort="1000.0" lower="-1.0" upper="1.0" velocity="1000.0"/>
  </joint>

  <link name="PlateFixLink15">
    <inertial>
      <origin rpy="0 0 0" xyz="0 0 0"/>
      <mass value="1"/>
      <inertia ixx="0.01" ixy="0" ixz="0" iyy="0.01" iyz="0" izz="0.01"/>
    </inertial>
  </link>

  <joint name="PlateFixJoint15b" type="fixed">
    <parent link="PlateFixLink15"/>
    <child link="Plate15"/>
    <origin rpy="0 0 0" xyz="0 0 0.028000"/>
    <axis xyz="-1 0 0"/>
  </joint>

  <link name="Plate15">
    <inertial>
      <origin rpy="0 0 0" xyz="0 0 0"/>
      <mass value="1"/>
      <inertia ixx="0.01" ixy="0" ixz="0" iyy="0.01" iyz="0" izz="0.01"/>
    </inertial>
    <visual>
      <origin rpy="0 0 0" xyz="0 0 0"/>
      <geometry>
        <cylinder radius="0.035000" length="0.025"/>
      </geometry>
      <material name="Black"/>
    </visual>
  </link>

  <!-- Section 16 -->

  <joint name="Joint_16a" type="revolute">
    <parent link="Plate15"/>
    <child link="Block16"/>
    <origin rpy="0 0 0" xyz="0 0 0.028000"/>
    <axis xyz="0 1 0"/>
    <limit effort="1000.0" lower="-1.0" upper="1.0" velocity="1000.0"/>
  </joint>

  <link name="Block16">
    <inertial>
      <origin rpy="0 0 0" xyz="0 0 0"/>
      <mass value="1"/>
      <inertia ixx="0.01" ixy="0" ixz="0" iyy="0.01" iyz="0" izz="0.01"/>
    </inertial>
    <visual>
      <origin rpy="0 0 0" xyz="0 0 0"/>
      <geometry>
        <box size="0.023 0.023 0.005"/>
      </geometry>
      <material name="Grey"/>
    </visual>
  </link>

  <joint name="Joint_16b" type="revolute">
    <parent link="Block16"/>
    <child link="PlateFixLink16"/>
    <origin rpy="0 0 0" xyz="0 0 0"/>
    <axis xyz="-1 0 0"/>
    <limit effort="1000.0" lower="-1.0" upper="1.0" velocity="1000.0"/>
  </joint>

  <link name="PlateFixLink16">
    <inertial>
      <origin rpy="0 0 0" xyz="0 0 0"/>
      <mass value="1"/>
      <inertia ixx="0.01" ixy="0" ixz="0" iyy="0.01" iyz="0" izz="0.01"/>
    </inertial>
  </link>

  <joint name="PlateFixJoint16b" type="fixed">
    <parent link="PlateFixLink16"/>
    <child link="Plate16"/>
    <origin rpy="0 0 0" xyz="0 0 0.028000"/>
    <axis xyz="-1 0 0"/>
  </joint>

  <link name="Plate16">
    <inertial>
      <origin rpy="0 0 0" xyz="0 0 0"/>
      <mass value="1"/>
      <inertia ixx="0.01" ixy="0" ixz="0" iyy="0.01" iyz="0" izz="0.01"/>
    </inertial>
    <visual>
      <origin rpy="0 0 0" xyz="0 0 0"/>
      <geometry>
        <cylinder radius="0.035000" length="0.025"/>
      </geometry>
      <material name="Grey"/>
    </visual>
  </link>

  <!-- Section 17 -->

  <joint name="Joint_17a" type="revolute">
    <parent link="Plate16"/>
    <child link="Block17"/>
    <origin rpy="0 0 0" xyz="0 0 0.028000"/>
    <axis xyz="0 1 0"/>
    <limit effort="1000.0" lower="-1.0" upper="1.0" velocity="1000.0"/>
  </joint>

  <link name="Block17">
    <inertial>
      <origin rpy="0 0 0" xyz="0 0 0"/>
      <mass value="1"/>
      <inertia ixx="0.01" ixy="0" ixz="0" iyy="0.01" iyz="0" izz="0.01"/>
    </inertial>
    <visual>
      <origin rpy="0 0 0" xyz="0 0 0"/>
      <geometry>
        <box size="0.023 0.023 0.005"/>
      </geometry>
      <material name="Grey"/>
    </visual>
  </link>

  <joint name="Joint_17b" type="revolute">
    <parent link="Block17"/>
    <child link="PlateFixLink17"/>
    <origin rpy="0 0 0" xyz="0 0 0"/>
    <axis xyz="-1 0 0"/>
    <limit effort="1000.0" lower="-1.0" upper="1.0" velocity="1000.0"/>
  </joint>

  <link name="PlateFixLink17">
    <inertial>
      <origin rpy="0 0 0" xyz="0 0 0"/>
      <mass value="1"/>
      <inertia ixx="0.01" ixy="0" ixz="0" iyy="0.01" iyz="0" izz="0.01"/>
    </inertial>
  </link>

  <joint name="PlateFixJoint17b" type="fixed">
    <parent link="PlateFixLink17"/>
    <child link="Plate17"/>
    <origin rpy="0 0 0" xyz="0 0 0.028000"/>
    <axis xyz="-1 0 0"/>
  </joint>

  <link name="Plate17">
    <inertial>
      <origin rpy="0 0 0" xyz="0 0 0"/>
      <mass value="1"/>
      <inertia ixx="0.01" ixy="0" ixz="0" iyy="0.01" iyz="0" izz="0.01"/>
    </inertial>
    <visual>
      <origin rpy="0 0 0" xyz="0 0 0"/>
      <geometry>
        <cylinder radius="0.035000" length="0.025"/>
      </geometry>
      <material name="Grey"/>
    </visual>
  </link>

  <!-- Section 18 -->

  <joint name="Joint_18a" type="revolute">
    <parent link="Plate17"/>
    <child link="Block18"/>
    <origin rpy="0 0 0" xyz="0 0 0.028000"/>
    <axis xyz="0 1 0"/>
    <limit effort="1000.0" lower="-1.0" upper="1.0" velocity="1000.0"/>
  </joint>

  <link name="Block18">
    <inertial>
      <origin rpy="0 0 0" xyz="0 0 0"/>
      <mass value="1"/>
      <inertia ixx="0.01" ixy="0" ixz="0" iyy="0.01" iyz="0" izz="0.01"/>
    </inertial>
    <visual>
      <origin rpy="0 0 0" xyz="0 0 0"/>
      <geometry>
        <box size="0.023 0.023 0.005"/>
      </geometry>
      <material name="Grey"/>
    </visual>
  </link>

  <joint name="Joint_18b" type="revolute">
    <parent link="Block18"/>
    <child link="PlateFixLink18"/>
    <origin rpy="0 0 0" xyz="0 0 0"/>
    <axis xyz="-1 0 0"/>
    <limit effort="1000.0" lower="-1.0" upper="1.0" velocity="1000.0"/>
  </joint>

  <link name="PlateFixLink18">
    <inertial>
      <origin rpy="0 0 0" xyz="0 0 0"/>
      <mass value="1"/>
      <inertia ixx="0.01" ixy="0" ixz="0" iyy="0.01" iyz="0" izz="0.01"/>
    </inertial>
  </link>

  <joint name="PlateFixJoint18b" type="fixed">
    <parent link="PlateFixLink18"/>
    <child link="Plate18"/>
    <origin rpy="0 0 0" xyz="0 0 0.028000"/>
    <axis xyz="-1 0 0"/>
  </joint>

  <link name="Plate18">
    <inertial>
      <origin rpy="0 0 0" xyz="0 0 0"/>
      <mass value="1"/>
      <inertia ixx="0.01" ixy="0" ixz="0" iyy="0.01" iyz="0" izz="0.01"/>
    </inertial>
    <visual>
      <origin rpy="0 0 0" xyz="0 0 0"/>
      <geometry>
        <cylinder radius="0.035000" length="0.025"/>
      </geometry>
      <material name="Grey"/>
    </visual>
  </link>

  <!-- Section 19 -->

  <joint name="Joint_19a" type="revolute">
    <parent link="Plate18"/>
    <child link="Block19"/>
    <origin rpy="0 0 0" xyz="0 0 0.028000"/>
    <axis xyz="0 1 0"/>
    <limit effort="1000.0" lower="-1.0" upper="1.0" velocity="1000.0"/>
  </joint>

  <link name="Block19">
    <inertial>
      <origin rpy="0 0 0" xyz="0 0 0"/>
      <mass value="1"/>
      <inertia ixx="0.01" ixy="0" ixz="0" iyy="0.01" iyz="0" izz="0.01"/>
    </inertial>
    <visual>
      <origin rpy="0 0 0" xyz="0 0 0"/>
      <geometry>
        <box size="0.023 0.023 0.005"/>
      </geometry>
      <material name="Grey"/>
    </visual>
  </link>

  <joint name="Joint_19b" type="revolute">
    <parent link="Block19"/>
    <child link="PlateFixLink19"/>
    <origin rpy="0 0 0" xyz="0 0 0"/>
    <axis xyz="-1 0 0"/>
    <limit effort="1000.0" lower="-1.0" upper="1.0" velocity="1000.0"/>
  </joint>

  <link name="PlateFixLink19">
    <inertial>
      <origin rpy="0 0 0" xyz="0 0 0"/>
      <mass value="1"/>
      <inertia ixx="0.01" ixy="0" ixz="0" iyy="0.01" iyz="0" izz="0.01"/>
    </inertial>
  </link>

  <joint name="PlateFixJoint19b" type="fixed">
    <parent link="PlateFixLink19"/>
    <child link="Plate19"/>
    <origin rpy="0 0 0" xyz="0 0 0.028000"/>
    <axis xyz="-1 0 0"/>
  </joint>

  <link name="Plate19">
    <inertial>
      <origin rpy="0 0 0" xyz="0 0 0"/>
      <mass value="1"/>
      <inertia ixx="0.01" ixy="0" ixz="0" iyy="0.01" iyz="0" izz="0.01"/>
    </inertial>
    <visual>
      <origin rpy="0 0 0" xyz="0 0 0"/>
      <geometry>
        <cylinder radius="0.035000" length="0.025"/>
      </geometry>
      <material name="Black"/>
    </visual>
  </link>

  <!-- Section 20 -->

  <joint name="Joint_20a" type="revolute">
    <parent link="Plate19"/>
    <child link="Block20"/>
    <origin rpy="0 0 0" xyz="0 0 0.028000"/>
    <axis xyz="0 1 0"/>
    <limit effort="1000.0" lower="-1.0" upper="1.0" velocity="1000.0"/>
  </joint>

  <link name="Block20">
    <inertial>
      <origin rpy="0 0 0" xyz="0 0 0"/>
      <mass value="1"/>
      <inertia ixx="0.01" ixy="0" ixz="0" iyy="0.01" iyz="0" izz="0.01"/>
    </inertial>
    <visual>
      <origin rpy="0 0 0" xyz="0 0 0"/>
      <geometry>
        <box size="0.023 0.023 0.005"/>
      </geometry>
      <material name="Grey"/>
    </visual>
  </link>

  <joint name="Joint_20b" type="revolute">
    <parent link="Block20"/>
    <child link="PlateFixLink20"/>
    <origin rpy="0 0 0" xyz="0 0 0"/>
    <axis xyz="-1 0 0"/>
    <limit effort="1000.0" lower="-1.0" upper="1.0" velocity="1000.0"/>
  </joint>

  <link name="PlateFixLink20">
    <inertial>
      <origin rpy="0 0 0" xyz="0 0 0"/>
      <mass value="1"/>
      <inertia ixx="0.01" ixy="0" ixz="0" iyy="0.01" iyz="0" izz="0.01"/>
    </inertial>
  </link>

  <joint name="PlateFixJoint20b" type="fixed">
    <parent link="PlateFixLink20"/>
    <child link="Plate20"/>
    <origin rpy="0 0 0" xyz="0 0 0.028000"/>
    <axis xyz="-1 0 0"/>
  </joint>

  <link name="Plate20">
    <inertial>
      <origin rpy="0 0 0" xyz="0 0 0"/>
      <mass value="1"/>
      <inertia ixx="0.01" ixy="0" ixz="0" iyy="0.01" iyz="0" izz="0.01"/>
    </inertial>
    <visual>
      <origin rpy="0 0 0" xyz="0 0 0"/>
      <geometry>
        <cylinder radius="0.035000" length="0.025"/>
      </geometry>
      <material name="Grey"/>
    </visual>
  </link>

  <!-- Section 21 -->

  <joint name="Joint_21a" type="revolute">
    <parent link="Plate20"/>
    <child link="Block21"/>
    <origin rpy="0 0 0" xyz="0 0 0.028000"/>
    <axis xyz="0 1 0"/>
    <limit effort="1000.0" lower="-1.0" upper="1.0" velocity="1000.0"/>
  </joint>

  <link name="Block21">
    <inertial>
      <origin rpy="0 0 0" xyz="0 0 0"/>
      <mass value="1"/>
      <inertia ixx="0.01" ixy="0" ixz="0" iyy="0.01" iyz="0" izz="0.01"/>
    </inertial>
    <visual>
      <origin rpy="0 0 0" xyz="0 0 0"/>
      <geometry>
        <box size="0.023 0.023 0.005"/>
      </geometry>
      <material name="Grey"/>
    </visual>
  </link>

  <joint name="Joint_21b" type="revolute">
    <parent link="Block21"/>
    <child link="PlateFixLink21"/>
    <origin rpy="0 0 0" xyz="0 0 0"/>
    <axis xyz="-1 0 0"/>
    <limit effort="1000.0" lower="-1.0" upper="1.0" velocity="1000.0"/>
  </joint>

  <link name="PlateFixLink21">
    <inertial>
      <origin rpy="0 0 0" xyz="0 0 0"/>
      <mass value="1"/>
      <inertia ixx="0.01" ixy="0" ixz="0" iyy="0.01" iyz="0" izz="0.01"/>
    </inertial>
  </link>

  <joint name="PlateFixJoint21b" type="fixed">
    <parent link="PlateFixLink21"/>
    <child link="Plate21"/>
    <origin rpy="0 0 0" xyz="0 0 0.028000"/>
    <axis xyz="-1 0 0"/>
  </joint>

  <link name="Plate21">
    <inertial>
      <origin rpy="0 0 0" xyz="0 0 0"/>
      <mass value="1"/>
      <inertia ixx="0.01" ixy="0" ixz="0" iyy="0.01" iyz="0" izz="0.01"/>
    </inertial>
    <visual>
      <origin rpy="0 0 0" xyz="0 0 0"/>
      <geometry>
        <cylinder radius="0.035000" length="0.025"/>
      </geometry>
      <material name="Grey"/>
    </visual>
  </link>

  <!-- Section 22 -->

  <joint name="Joint_22a" type="revolute">
    <parent link="Plate21"/>
    <child link="Block22"/>
    <origin rpy="0 0 0" xyz="0 0 0.028000"/>
    <axis xyz="0 1 0"/>
    <limit effort="1000.0" lower="-1.0" upper="1.0" velocity="1000.0"/>
  </joint>

  <link name="Block22">
    <inertial>
      <origin rpy="0 0 0" xyz="0 0 0"/>
      <mass value="1"/>
      <inertia ixx="0.01" ixy="0" ixz="0" iyy="0.01" iyz="0" izz="0.01"/>
    </inertial>
    <visual>
      <origin rpy="0 0 0" xyz="0 0 0"/>
      <geometry>
        <box size="0.023 0.023 0.005"/>
      </geometry>
      <material name="Grey"/>
    </visual>
  </link>

  <joint name="Joint_22b" type="revolute">
    <parent link="Block22"/>
    <child link="PlateFixLink22"/>
    <origin rpy="0 0 0" xyz="0 0 0"/>
    <axis xyz="-1 0 0"/>
    <limit effort="1000.0" lower="-1.0" upper="1.0" velocity="1000.0"/>
  </joint>

  <link name="PlateFixLink22">
    <inertial>
      <origin rpy="0 0 0" xyz="0 0 0"/>
      <mass value="1"/>
      <inertia ixx="0.01" ixy="0" ixz="0" iyy="0.01" iyz="0" izz="0.01"/>
    </inertial>
  </link>

  <joint name="PlateFixJoint22b" type="fixed">
    <parent link="PlateFixLink22"/>
    <child link="Plate22"/>
    <origin rpy="0 0 0" xyz="0 0 0.028000"/>
    <axis xyz="-1 0 0"/>
  </joint>

  <link name="Plate22">
    <inertial>
      <origin rpy="0 0 0" xyz="0 0 0"/>
      <mass value="1"/>
      <inertia ixx="0.01" ixy="0" ixz="0" iyy="0.01" iyz="0" izz="0.01"/>
    </inertial>
    <visual>
      <origin rpy="0 0 0" xyz="0 0 0"/>
      <geometry>
        <cylinder radius="0.035000" length="0.025"/>
      </geometry>
      <material name="Grey"/>
    </visual>
  </link>

  <!-- Section 23 -->

  <joint name="Joint_23a" type="revolute">
    <parent link="Plate22"/>
    <child link="Block23"/>
    <origin rpy="0 0 0" xyz="0 0 0.028000"/>
    <axis xyz="0 1 0"/>
    <limit effort="1000.0" lower="-1.0" upper="1.0" velocity="1000.0"/>
  </joint>

  <link name="Block23">
    <inertial>
      <origin rpy="0 0 0" xyz="0 0 0"/>
      <mass value="1"/>
      <inertia ixx="0.01" ixy="0" ixz="0" iyy="0.01" iyz="0" izz="0.01"/>
    </inertial>
    <visual>
      <origin rpy="0 0 0" xyz="0 0 0"/>
      <geometry>
        <box size="0.023 0.023 0.005"/>
      </geometry>
      <material name="Grey"/>
    </visual>
  </link>

  <joint name="Joint_23b" type="revolute">
    <parent link="Block23"/>
    <child link="PlateFixLink23"/>
    <origin rpy="0 0 0" xyz="0 0 0"/>
    <axis xyz="-1 0 0"/>
    <limit effort="1000.0" lower="-1.0" upper="1.0" velocity="1000.0"/>
  </joint>

  <link name="PlateFixLink23">
    <inertial>
      <origin rpy="0 0 0" xyz="0 0 0"/>
      <mass value="1"/>
      <inertia ixx="0.01" ixy="0" ixz="0" iyy="0.01" iyz="0" izz="0.01"/>
    </inertial>
  </link>

  <joint name="PlateFixJoint23b" type="fixed">
    <parent link="PlateFixLink23"/>
    <child link="Plate23"/>
    <origin rpy="0 0 0" xyz="0 0 0.028000"/>
    <axis xyz="-1 0 0"/>
  </joint>

  <link name="Plate23">
    <inertial>
      <origin rpy="0 0 0" xyz="0 0 0"/>
      <mass value="1"/>
      <inertia ixx="0.01" ixy="0" ixz="0" iyy="0.01" iyz="0" izz="0.01"/>
    </inertial>
    <visual>
      <origin rpy="0 0 0" xyz="0 0 0"/>
      <geometry>
        <cylinder radius="0.035000" length="0.025"/>
      </geometry>
      <material name="Black"/>
    </visual>
  </link>

  <joint name="Joint_Camera" type="fixed">
    <parent link="Plate23"/>
    <child link="CameraBox"/>
    <origin rpy="0 0 0" xyz="0 0 0.000000"/>
    <axis xyz="0 0 1"/>
  </joint>

  <link name="CameraBox">
    <inertial>
      <origin rpy="0 0 0" xyz="0 0 0"/>
      <mass value="1"/>
      <inertia ixx="0.01" ixy="0" ixz="0" iyy="0.01" iyz="0" izz="0.01"/>
    </inertial>
    <visual>
      <origin rpy="0 0 0" xyz="0 0 0"/>
      <geometry>
        <sphere radius="0.005000"/>
      </geometry>
      <material name="Black"/>
    </visual>
  </link>

</robot>
